Workbook

Sheet Ringkasan
A1: RumahAgen — Dashboard Analytics (Contoh Export)
A2: Rentang 27 Agu 2026 – 25 Sep 2026 (30 hari) | Pembanding 28 Jul 2026 – 26 Agu 2026 | Data per 25 Sep 2026 | Definisi: Metric Definitions v1.1
A3: DATA CONTOH untuk uji format export. Angka ilustrasi, bukan data nyata RumahAgen.
A4: Diekspor oleh: Superadmin (contoh). Export dicatat di audit log.
A6: Ringkasan | B6: Periode ini | C6: Periode sebelumnya | D6: Perubahan
A7: Agen Aktif | B7: =Pengguna!B8 -> 1838 | C7: =Pengguna!C8 -> 1720 | D7: =Pengguna!D8 -> 0.068604651
A8: Agen Baru | B8: =Pengguna!B9 -> 473 | C8: =Pengguna!C9 -> 398 | D8: =Pengguna!D9 -> 0.18844221
A9: Listing Baru (dipublikasikan) | B9: =Marketplace!B8 -> 1234 | C9: =Marketplace!C8 -> 1065 | D9: =Marketplace!D8 -> 0.15868545
A10: Lead Unik | B10: =Marketplace!B10 -> 3003 | C10: =Marketplace!C10 -> 2481 | D10: =Marketplace!D10 -> 0.21039903
A11: Nilai Transaksi Net (Rp) | B11: =Komersial!B12 -> 378437108 | C11: =Komersial!C12 -> 314023944 | D11: =Komersial!D12 -> 0.20512182
A12: MRR (Rp) | B12: =Komersial!B11 -> 140071198 | C12: =Komersial!C11 -> 127134020 | D12: =Komersial!D11 -> 0.10176016
A14: Kelompok metrik
A15: Pengguna | B15: Agen aktif, agen baru, total per role, dormant, suspended
A16: Marketplace | B16: Listing, lead, refresh, proyek, klaim, konversi, kesehatan marketplace
A17: Organisasi | B17: Organisasi baru dan aktif
A18: Learning | B18: Pendaftar, penyelesaian, poin, sertifikat
A19: Komersial | B19: GMV, net, langganan vs add-on, subscriber, MRR/ARR, refund rate, ARPU, churn
A20: Aktivitas | B20: DAU, WAU, MAU, stickiness, churn agen
A21: Risiko | B21: Moderasi, banding, rekonsiliasi, rasio suspended
A22: Funnel_Kohort | B22: Funnel aktivasi dan retensi kohort
A24: Legenda: biru = angka masukan contoh; hitam = rumus; hijau = tautan antar sheet.

Sheet Pengguna
A1: Pengguna & Agen
A2: Rentang 27 Agu 2026 – 25 Sep 2026 (30 hari) | Pembanding 28 Jul 2026 – 26 Agu 2026
A3: DATA CONTOH untuk uji format export. Angka ilustrasi, bukan data nyata RumahAgen.
A4: Agen aktif = minimal 1 aktivitas bermakna (login, buat/ubah/refresh listing, terima lead) dalam 30 hari. Staf, akun uji, dan terhapus dikeluarkan.
A6: Ringkasan periode
A7: Metrik | B7: Periode ini | C7: Periode sebelumnya | D7: Perubahan
A8: Agen Aktif (posisi akhir) | B8: =B43 -> 1838 | C8: =B76 -> 1720 | D8: =IF(C8=0,"",B8/C8-1) -> 0.068604651
A9: Agen Baru (total) | B9: =SUM(C14:C43) -> 473 | C9: =SUM(C47:C76) -> 398 | D9: =IF(C9=0,"",B9/C9-1) -> 0.18844221
A12: Data harian, periode ini
A13: Tanggal | B13: Agen Aktif | C13: Agen Baru
A14: 46261 | B14: 1716 | C14: 15
A15: 46262 | B15: 1727 | C15: 14
A16: 46263 | B16: 1729 | C16: 12
A17: 46264 | B17: 1732 | C17: 11
A18: 46265 | B18: 1734 | C18: 14
A19: 46266 | B19: 1745 | C19: 15
A20: 46267 | B20: 1748 | C20: 17
A21: 46268 | B21: 1749 | C21: 17
A22: 46269 | B22: 1754 | C22: 16
A23: 46270 | B23: 1758 | C23: 13
A24: 46271 | B24: 1756 | C24: 12
A25: 46272 | B25: 1767 | C25: 14
... A43: 46290 | B43: 1838 | C43: 18
A45: Data harian, periode pembanding
A46: Tanggal | B46: Agen Aktif | C46: Agen Baru
A47: 46231 | B47: 1592 | C47: 14
A48: 46232 | B48: 1604 | C48: 11
A49: 46233 | B49: 1599 | C49: 10
A50: 46234 | B50: 1603 | C50: 11
A51: 46235 | B51: 1605 | C51: 12
A52: 46236 | B52: 1610 | C52: 15
A53: 46237 | B53: 1620 | C53: 15
A54: 46238 | B54: 1628 | C54: 14
A55: 46239 | B55: 1628 | C55: 12
A56: 46240 | B56: 1626 | C56: 10
A57: 46241 | B57: 1637 | C57: 12
A58: 46242 | B58: 1637 | C58: 13
... A76: 46260 | B76: 1720 | C76: 13
A79: Total pengguna per role (posisi akhir)
A80: Role | B80: Jumlah | C80: Porsi
...

Sheet Marketplace
A1: Marketplace
A2: Rentang 27 Agu 2026 – 25 Sep 2026 (30 hari) | Pembanding 28 Jul 2026 – 26 Agu 2026
A3: DATA CONTOH untuk uji format export. Angka ilustrasi, bukan data nyata RumahAgen.
A4: Lead = klik CTA WhatsApp; lead unik didedup per pengunjung per listing per hari. Klik pemilik listing dan bot dikeluarkan.
A6: Ringkasan periode
A7: Metrik | B7: Periode ini | C7: Periode sebelumnya | D7: Perubahan
A8: Listing Baru (dipublikasikan) (total) | B8: =SUM(B19:B48) -> 1234 | C8: =SUM(B52:B81) -> 1065 | D8: =IF(C8=0,"",B8/C8-1) -> 0.15868545
A9: Lead Total (total) | B9: =SUM(C19:C48) -> 4080 | C9: =SUM(C52:C81) -> 3414 | D9: =IF(C9=0,"",B9/C9-1) -> 0.19507909
A10: Lead Unik (total) | B10: =SUM(D19:D48) -> 3003 | C10: =SUM(D52:D81) -> 2481 | D10: =IF(C10=0,"",B10/C10-1) -> 0.21039903
A11: Refresh Listing (total) | B11: =SUM(E19:E48) -> 6821 | C11: =SUM(E52:E81) -> 5806 | D11: =IF(C11=0,"",B11/C11-1) -> 0.17481915
A12: Proyek Developer Baru (total) | B12: =SUM(F19:F48) -> 44 | C12: =SUM(F52:F81) -> 32 | D12: =IF(C12=0,"",B12/C12-1) -> 0.375
A13: Klaim Proyek Disetujui (total) | B13: =SUM(G19:G48) -> 108 | C13: =SUM(G52:G81) -> 88 | D13: =IF(C13=0,"",B13/C13-1) -> 0.22727273
A14: Konversi Pengunjung ke Lead (%) (posisi akhir) | B14: =H48 -> 3.46 | C14: =H81 -> 3.07 | D14: =IF(C14=0,"",B14/C14-1) -> 0.12703583
A17: Data harian, periode ini
A18: Tanggal | B18: Listing Baru (dipublikasikan) | C18: Lead Total | D18: Lead Unik | E18: Refresh Listing | F18: Proyek Developer Baru | G18: Klaim Proyek Disetujui | H18: Konversi Pengunjung ke Lead (%)
A19: 46261 | B19: 38 | C19: 99 | D19: 68 | E19: 211 | F19: 2 | G19: 4 | H19: 3.11
A20: 46262 | B20: 33 | C20: 104 | D20: 79 | E20: 241 | F20: 2 | G20: 4 | H20: 3.11
A21: 46263 | B21: 31 | C21: 113 | D21: 93 | E21: 238 | F21: 2 | G21: 3 | H21: 3.12
A22: 46264 | B22: 37 | C22: 126 | D22: 110 | E22: 226 | F22: 1 | G22: 3 | H22: 3.13
A23: 46265 | B23: 42 | C23: 141 | D23: 100 | E23: 216 | F23: 1 | G23: 3 | H23: 3.15
A24: 46266 | B24: 48 | C24: 141 | D24: 87 | E24: 170 | F24: 1 | G24: 3 | H24: 3.16
A25: 46267 | B25: 46 | C25: 135 | D25: 81 | E25: 174 | F25: 1 | G25: 4 | H25: 3.16
A26: 46268 | B26: 39 | C26: 110 | D26: 83 | E26: 198 | F26: 2 | G26: 4 | H26: 3.17
A27: 46269 | B27: 37 | C27: 99 | D27: 90 | E27: 246 | F27: 2 | G27: 4 | H27: 3.19
A28: 46270 | B28: 31 | C28: 120 | D28: 110 | E28: 257 | F28: 2 | G28: 3 | H28: 3.22
A29: 46271 | B29: 36 | C29: 143 | D29: 118 | E29: 253 | F29: 1 | G29: 3 | H29: 3.23
A30: 46272 | B30: 44 | C30: 160 | D30: 110 | E30: 223 | F30: 1 | G30: 3 | H30: 3.23
... A48: 46290 | B48: 39 | C48: 129 | D48: 112 | E48: 261 | F48: 2 | G48: 4 | H48: 3.46
A50: Data harian, periode pembanding
A51: Tanggal | B51: Listing Baru (dipublikasikan) | C51: Lead Total | D51: Lead Unik | E51: Refresh Listing | F51: Proyek Developer Baru | G51: Klaim Proyek Disetujui | H51: Konversi Pengunjung ke Lead (%)
A52: 46231 | B52: 32 | C52: 92 | D52: 71 | E52: 198 | F52: 1 | G52: 3 | H52: 2.73
A53: 46232 | B53: 29 | C53: 90 | D53: 82 | E53: 226 | F53: 1 | G53: 3 | H53: 2.76
A54: 46233 | B54: 32 | C54: 110 | D54: 94 | E54: 227 | F54: 1 | G54: 2 | H54: 2.76
A55: 46234 | B55: 37 | C55: 130 | D55: 97 | E55: 190 | F55: 1 | G55: 2 | H55: 2.77
A56: 46235 | B56: 39 | C56: 132 | D56: 79 | E56: 161 | F56: 1 | G56: 3 | H56: 2.78
A57: 46236 | B57: 40 | C57: 121 | D57: 68 | E57: 157 | F57: 1 | G57: 3 | H57: 2.79
A58: 46237 | B58: 38 | C58: 98 | D58: 64 | E58: 170 | F58: 1 | G58: 3 | H58: 2.8
A59: 46238 | B59: 31 | C59: 93 | D59: 69 | E59: 198 | F59: 1 | G59: 3 | H59: 2.81
A60: 46239 | B60: 30 | C60: 106 | D60: 86 | E60: 224 | F60: 1 | G60: 3 | H60: 2.83
A61: 46240 | B61: 29 | C61: 118 | D61: 93 | E61: 210 | F61: 1 | G61: 2 | H61: 2.86
...

Sheet Organisasi
A1: Organisasi
A2: Rentang 27 Agu 2026 – 25 Sep 2026 (30 hari) | Pembanding 28 Jul 2026 – 26 Agu 2026
A3: DATA CONTOH untuk uji format export. Angka ilustrasi, bukan data nyata RumahAgen.
A4: Organisasi aktif = status active, tidak dalam penutupan, tidak suspended. Tren penutupan tidak ditampilkan.
A6: Ringkasan periode
A7: Metrik | B7: Periode ini | C7: Periode sebelumnya | D7: Perubahan
A8: Organisasi Baru (total) | B8: =SUM(B14:B43) -> 67 | C8: =SUM(B47:B76) -> 60 | D8: =IF(C8=0,"",B8/C8-1) -> 0.11666667
A9: Organisasi Aktif (posisi akhir) | B9: =C43 -> 213 | C9: =C76 -> 195 | D9: =IF(C9=0,"",B9/C9-1) -> 0.092307692
A12: Data harian, periode ini
A13: Tanggal | B13: Organisasi Baru | C13: Organisasi Aktif
A14: 46261 | B14: 2 | C14: 196
A15: 46262 | B15: 2 | C15: 197
A16: 46263 | B16: 2 | C16: 198
A17: 46264 | B17: 2 | C17: 198
A18: 46265 | B18: 2 | C18: 198
A19: 46266 | B19: 2 | C19: 199
A20: 46267 | B20: 2 | C20: 200
A21: 46268 | B21: 2 | C21: 200
A22: 46269 | B22: 2 | C22: 201
A23: 46270 | B23: 2 | C23: 201
A24: 46271 | B24: 2 | C24: 202
A25: 46272 | B25: 2 | C25: 203
... A43: 46290 | B43: 2 | C43: 213
A45: Data harian, periode pembanding
A46: Tanggal | B46: Organisasi Baru | C46: Organisasi Aktif
A47: 46231 | B47: 2 | C47: 178
A48: 46232 | B48: 2 | C48: 179
A49: 46233 | B49: 2 | C49: 180
A50: 46234 | B50: 2 | C50: 181
A51: 46235 | B51: 2 | C51: 181
A52: 46236 | B52: 2 | C52: 182
A53: 46237 | B53: 2 | C53: 182
A54: 46238 | B54: 2 | C54: 183
A55: 46239 | B55: 2 | C55: 182
A56: 46240 | B56: 2 | C56: 184
A57: 46241 | B57: 2 | C57: 185
A58: 46242 | B58: 2 | C58: 185
... A76: 46260 | B76: 2 | C76: 195

Sheet Learning
A1: Learning RumahAgen
A2: Rentang 27 Agu 2026 – 25 Sep 2026 (30 hari) | Pembanding 28 Jul 2026 – 26 Agu 2026
A3: DATA CONTOH untuk uji format export. Angka ilustrasi, bukan data nyata RumahAgen.
A4: Menyelesaikan = completion qualifying. Completion rate dihitung per kohort pendaftaran.
A6: Ringkasan periode
A7: Metrik | B7: Periode ini | C7: Periode sebelumnya | D7: Perubahan
A8: Pendaftar Learning (pendaftaran) (total) | B8: =SUM(B17:B46) -> 852 | C8: =SUM(B50:B79) -> 725 | D8: =IF(C8=0,"",B8/C8-1) -> 0.17517241
A9: Pendaftar Learning (pengguna unik) (total) | B9: =SUM(C17:C46) -> 618 | C9: =SUM(C50:C79) -> 546 | D9: =IF(C9=0,"",B9/C9-1) -> 0.13186813
A10: Menyelesaikan Learning (qualifying) (total) | B10: =SUM(D17:D46) -> 365 | C10: =SUM(D50:D79) -> 308 | D10: =IF(C10=0,"",B10/C10-1) -> 0.18506494
A11: Learning Points Diterbitkan (total) | B11: =SUM(E17:E46) -> 15916 | C11: =SUM(E50:E79) -> 13581 | D11: =IF(C11=0,"",B11/C11-1) -> 0.17193137
A12: Sertifikat Diterbitkan (total) | B12: =SUM(F17:F46) -> 187 | C12: =SUM(F50:F79) -> 155 | D12: =IF(C12=0,"",B12/C12-1) -> 0.20645161
A15: Data harian, periode ini
A16: Tanggal | B16: Pendaftar Learning (pendaftaran) | C16: Pendaftar Learning (pengguna unik) | D16: Menyelesaikan Learning (qualifying) | E16: Learning Points Diterbitkan | F16: Sertifikat Diterbitkan
A17: 46261 | B17: 22 | C17: 17 | D17: 12 | E17: 588 | F17: 6
A18: 46262 | B18: 22 | C18: 20 | D18: 13 | E18: 520 | F18: 5
A19: 46263 | B19: 27 | C19: 23 | D19: 13 | E19: 434 | F19: 5
A20: 46264 | B20: 32 | C20: 23 | D20: 11 | E20: 417 | F20: 5
A21: 46265 | B21: 32 | C21: 19 | D21: 10 | E21: 435 | F21: 6
A22: 46266 | B22: 29 | C22: 17 | D22: 9 | E22: 517 | F22: 6
A23: 46267 | B23: 24 | C23: 16 | D23: 10 | E23: 583 | F23: 7
A24: 46268 | B24: 23 | C24: 17 | D24: 12 | E24: 588 | F24: 6
A25: 46269 | B25: 26 | C25: 21 | D25: 14 | E25: 559 | F25: 5
A26: 46270 | B26: 29 | C26: 23 | D26: 13 | E26: 460 | F26: 5
A27: 46271 | B27: 32 | C27: 22 | D27: 11 | E27: 395 | F27: 5
A28: 46272 | B28: 32 | C28: 21 | D28: 10 | E28: 420 | F28: 6
... A46: 46290 | B46: 28 | C46: 25 | D46: 15 | E46: 636 | F46: 6
A48: Data harian, periode pembanding
A49: Tanggal | B49: Pendaftar Learning (pendaftaran) | C49: Pendaftar Learning (pengguna unik) | D49: Menyelesaikan Learning (qualifying) | E49: Learning Points Diterbitkan | F49: Sertifikat Diterbitkan
A50: 46231 | B50: 21 | C50: 18 | D50: 11 | E50: 479 | F50: 5
A51: 46232 | B51: 24 | C51: 20 | D51: 11 | E51: 404 | F51: 4
A52: 46233 | B52: 26 | C52: 21 | D52: 10 | E52: 369 | F52: 4
A53: 46234 | B53: 27 | C53: 19 | D53: 8 | E53: 374 | F53: 5
A54: 46235 | B54: 25 | C54: 15 | D54: 9 | E54: 415 | F54: 6
A55: 46236 | B55: 22 | C55: 13 | D55: 8 | E55: 480 | F55: 6
A56: 46237 | B56: 19 | C56: 16 | D56: 10 | E56: 529 | F56: 6
A57: 46238 | B57: 19 | C57: 18 | D57: 12 | E57: 503 | F57: 5
A58: 46239 | B58: 24 | C58: 21 | D58: 11 | E58: 430 | F58: 4
A59: 46240 | B59: 29 | C59: 20 | D59: 11 | E59: 381 | F59: 5
A60: 46241 | B60: 29 | C60: 18 | D60: 9 | E60: 380 | F60: 5
A61: 46242 | B61: 25 | C61: 15 | D61: 8 | E61: 442 | F61: 6
...

Sheet Komersial
A1: Komersial
A2: Rentang 27 Agu 2026 – 25 Sep 2026 (30 hari) | Pembanding 28 Jul 2026 – 26 Agu 2026
A3: DATA CONTOH untuk uji format export. Angka ilustrasi, bukan data nyata RumahAgen.
A4: Transaksi sukses = settlement/capture terverifikasi. Net = gross dikurangi refund dan chargeback. Tanggal transaksi = paid_at. Free membership tidak dihitung subscriber.
A6: Ringkasan periode
A7: Metrik | B7: Periode ini | C7: Periode sebelumnya | D7: Perubahan
A8: GMV Gross (Rp) (total) | B8: =SUM(B19:B48) -> 392569614 | C8: =SUM(B52:B81) -> 325750976 | D8: =IF(C8=0,"",B8/C8-1) -> 0.20512184
A9: Subscriber Aktif (posisi akhir) | B9: =C48 -> 312 | C9: =C81 -> 279 | D9: =IF(C9=0,"",B9/C9-1) -> 0.11827957
A10: Pembeli Add-on (unik) (total) | B10: =SUM(D19:D48) -> 230 | C10: =SUM(D52:D81) -> 193 | D10: =IF(C10=0,"",B10/C10-1) -> 0.19170984
A11: MRR (Rp) (posisi akhir) | B11: =E48 -> 140071198 | C11: =E81 -> 127134020 | D11: =IF(C11=0,"",B11/C11-1) -> 0.10176016
A12: Nilai Transaksi Net (Rp) (total) | B12: =SUM(F19:F48) -> 378437108 | C12: =SUM(F52:F81) -> 314023944 | D12: =IF(C12=0,"",B12/C12-1) -> 0.20512182
A13: Pendapatan Langganan (Rp) (total) | B13: =SUM(G19:G48) -> 245605683 | C13: =SUM(G52:G81) -> 203801542 | D13: =IF(C13=0,"",B13/C13-1) -> 0.20512181
A14: Pendapatan Add-on (Rp) (total) | B14: =SUM(H19:H48) -> 132831425 | C14: =SUM(H52:H81) -> 110222402 | D14: =IF(C14=0,"",B14/C14-1) -> 0.20512185
A17: Data harian, periode ini
A18: Tanggal | B18: GMV Gross (Rp) | C18: Subscriber Aktif | D18: Pembeli Add-on (unik) | E18: MRR (Rp) | F18: Nilai Transaksi Net (Rp) | G18: Pendapatan Langganan (Rp) | H18: Pendapatan Add-on (Rp)
A19: 46261 | B19: 12002602 | C19: 280 | D19: 7 | E19: 128237611 | F19: 11570508 | G19: 7509260 | H19: 4061248
A20: 46262 | B20: 13031609 | C20: 280 | D20: 6 | E20: 128565164 | F20: 12562471 | G20: 8153044 | H20: 4409427
A21: 46263 | B21: 13820898 | C21: 281 | D21: 6 | E21: 129267364 | F21: 13323346 | G21: 8646852 | H21: 4676494
A22: 46264 | B22: 12464922 | C22: 282 | D22: 7 | E22: 129810748 | F22: 12016185 | G22: 7798504 | H22: 4217681
A23: 46265 | B23: 10022101 | C23: 284 | D23: 8 | E23: 130307122 | F23: 9661305 | G23: 6270187 | H23: 3391118
A24: 46266 | B24: 9074758 | C24: 286 | D24: 9 | E24: 130725034 | F24: 8748067 | G24: 5677495 | H24: 3070572
A25: 46267 | B25: 10946923 | C25: 287 | D25: 8 | E25: 130916422 | F25: 10552834 | G25: 6848789 | H25: 3704045
A26: 46268 | B26: 12066991 | C26: 286 | D26: 7 | E26: 131358368 | F26: 11632579 | G26: 7549544 | H26: 4083035
A27: 46269 | B27: 14539852 | C27: 287 | D27: 6 | E27: 130956353 | F27: 14016417 | G27: 9096655 | H27: 4919762
A28: 46270 | B28: 13638230 | C28: 290 | D28: 7 | E28: 131894824 | F28: 13147254 | G28: 8532568 | H28: 4614686
A29: 46271 | B29: 12918175 | C29: 290 | D29: 7 | E29: 132727234 | F29: 12453121 | G29: 8082076 | H29: 4371045
A30: 46272 | B30: 10606084 | C30: 292 | D30: 8 | E30: 132589432 | F30: 10224265 | G30: 6635548 | H30: 3588717
... A48: 46290 | B48: 17225709 | C48: 312 | D48: 7 | E48: 140071198 | F48: 16605583 | G48: 10777023 | H48: 5828560
A50: Data harian, periode pembanding
A51: Tanggal | B51: GMV Gross (Rp) | C51: Subscriber Aktif | D51: Pembeli Add-on (unik) | E51: MRR (Rp) | F51: Nilai Transaksi Net (Rp) | G51: Pendapatan Langganan (Rp) | H51: Pendapatan Add-on (Rp)
A52: 46231 | B52: 11289479 | C52: 246 | D52: 5 | E52: 115301066 | F52: 10883058 | G52: 7063105 | H52: 3819953
A53: 46232 | B53: 11631697 | C53: 249 | D53: 5 | E53: 115828481 | F53: 11212956 | G53: 7277208 | H53: 3935748
A54: 46233 | B54: 11133062 | C54: 249 | D54: 6 | E54: 116779556 | F54: 10732272 | G54: 6965245 | H54: 3767027
A55: 46234 | B55: 9117165 | C55: 250 | D55: 7 | E55: 116143684 | F55: 8788947 | G55: 5704027 | H55: 3084920
A56: 46235 | B56: 8957400 | C56: 250 | D56: 7 | E56: 117020184 | F56: 8634934 | G56: 5604072 | H56: 3030862
A57: 46236 | B57: 8290071 | C57: 251 | D57: 7 | E57: 117049036 | F57: 7991628 | G57: 5186567 | H57: 2805061
A58: 46237 | B58: 10569113 | C58: 254 | D58: 7 | E58: 117356935 | F58: 10188625 | G58: 6612418 | H58: 3576207
A59: 46238 | B59: 11662244 | C59: 254 | D59: 5 | E59: 117908266 | F59: 11242403 | G59: 7296320 | H59: 3946083
A60: 46239 | B60: 11732058 | C60: 255 | D60: 5 | E60: 118458722 | F60: 11309704 | G60: 7339998 | H60: 3969706
A61: 46240 | B61: 11614148 | C61: 257 | D61: 6 | E61: 118680978 | F61: 11196039 | G61: 7266229 | H61: 3929810
...

Sheet Aktivitas
A1: Aktivitas & Retensi
A2: Rentang 27 Agu 2026 – 25 Sep 2026 (30 hari) | Pembanding 28 Jul 2026 – 26 Agu 2026
A3: DATA CONTOH untuk uji format export. Angka ilustrasi, bukan data nyata RumahAgen.
A4: DAU/WAU/MAU dihitung dari agen aktif. Stickiness = rata-rata DAU / MAU akhir.
A6: Ringkasan periode
A7: Metrik | B7: Periode ini | C7: Periode sebelumnya | D7: Perubahan
A8: DAU (posisi akhir) | B8: =B44 -> 350 | C8: =B77 -> 308 | D8: =IF(C8=0,"",B8/C8-1) -> 0.13636364
A9: WAU (posisi akhir) | B9: =C44 -> 949 | C9: =C77 -> 878 | D9: =IF(C9=0,"",B9/C9-1) -> 0.080865604
A10: MAU (posisi akhir) | B10: =D44 -> 1837 | C10: =D77 -> 1718 | D10: =IF(C10=0,"",B10/C10-1) -> 0.069266589
A13: Data harian, periode ini
A14: Tanggal | B14: DAU | C14: WAU | D14: MAU
A15: 46261 | B15: 309 | C15: 880 | D15: 1719
A16: 46262 | B16: 313 | C16: 881 | D16: 1724
A17: 46263 | B17: 312 | C17: 886 | D17: 1734
A18: 46264 | B18: 314 | C18: 890 | D18: 1727
A19: 46265 | B19: 314 | C19: 888 | D19: 1736
A20: 46266 | B20: 315 | C20: 891 | D20: 1736
A21: 46267 | B21: 318 | C21: 897 | D21: 1740
A22: 46268 | B22: 319 | C22: 894 | D22: 1745
A23: 46269 | B23: 320 | C23: 900 | D23: 1751
A24: 46270 | B24: 322 | C24: 900 | D24: 1753
A25: 46271 | B25: 322 | C25: 900 | D25: 1756
A26: 46272 | B26: 327 | C26: 908 | D26: 1772
... A44: 46290 | B44: 350 | C44: 949 | D44: 1837
A46: Data harian, periode pembanding
A47: Tanggal | B47: DAU | C47: WAU | D47: MAU
A48: 46231 | B48: 270 | C48: 810 | D48: 1592
A49: 46232 | B49: 269 | C49: 812 | D49: 1604
A50: 46233 | B50: 271 | C50: 813 | D50: 1605
A51: 46234 | B51: 274 | C51: 816 | D51: 1610
A52: 46235 | B52: 275 | C52: 820 | D52: 1612
A53: 46236 | B53: 276 | C53: 819 | D53: 1614
A54: 46237 | B54: 276 | C54: 825 | D54: 1613
A55: 46238 | B55: 276 | C55: 830 | D55: 1622
A56: 46239 | B56: 280 | C56: 830 | D56: 1623
A57: 46240 | B57: 279 | C57: 831 | D57: 1637
A58: 46241 | B58: 284 | C58: 833 | D58: 1632
A59: 46242 | B59: 284 | C59: 838 | D59: 1645
... A77: 46260 | B77: 308 | C77: 878 | D77: 1718
A80: Stickiness (rata-rata DAU / MAU akhir) | B80: =AVERAGE(B15:B44)/D44 -> 0.17956814
...

Sheet Risiko
A1: Kualitas & Risiko
A2: Rentang 27 Agu 2026 – 25 Sep 2026 (30 hari) | Pembanding 28 Jul 2026 – 26 Agu 2026
A3: DATA CONTOH untuk uji format export. Angka ilustrasi, bukan data nyata RumahAgen.
A4: Suspended hanya sebagai rasio saat ini; tren suspended dan penutupan organisasi tidak ditampilkan.
A6: Ringkasan periode
A7: Metrik | B7: Periode ini | C7: Periode sebelumnya | D7: Perubahan
A8: Listing Ditolak Moderasi (total) | B8: =SUM(B14:B43) -> 123 | C8: =SUM(B47:B76) -> 111 | D8: =IF(C8=0,"",B8/C8-1) -> 0.10810811
A9: Banding Penghargaan Masuk (total) | B9: =SUM(C14:C43) -> 30 | C9: =SUM(C47:C76) -> 30 | D9: =IF(C9=0,"",B9/C9-1) -> 0
A12: Data harian, periode ini
A13: Tanggal | B13: Listing Ditolak Moderasi | C13: Banding Penghargaan Masuk
A14: 46261 | B14: 4 | C14: 1
A15: 46262 | B15: 5 | C15: 1
A16: 46263 | B16: 5 | C16: 1
A17: 46264 | B17: 4 | C17: 1
A18: 46265 | B18: 4 | C18: 1
A19: 46266 | B19: 3 | C19: 1
A20: 46267 | B20: 3 | C20: 1
A21: 46268 | B21: 4 | C21: 1
A22: 46269 | B22: 5 | C22: 1
A23: 46270 | B23: 5 | C23: 1
A24: 46271 | B24: 5 | C24: 1
A25: 46272 | B25: 4 | C25: 1
... A43: 46290 | B43: 4 | C43: 1
A45: Data harian, periode pembanding
A46: Tanggal | B46: Listing Ditolak Moderasi | C46: Banding Penghargaan Masuk
A47: 46231 | B47: 4 | C47: 1
A48: 46232 | B48: 5 | C48: 1
A49: 46233 | B49: 4 | C49: 1
A50: 46234 | B50: 4 | C50: 1
A51: 46235 | B51: 3 | C51: 1
A52: 46236 | B52: 3 | C52: 1
A53: 46237 | B53: 3 | C53: 1
A54: 46238 | B54: 4 | C54: 1
A55: 46239 | B55: 5 | C55: 1
A56: 46240 | B56: 4 | C56: 1
A57: 46241 | B57: 4 | C57: 1
A58: 46242 | B58: 3 | C58: 1
... A76: 46260 | B76: 4 | C76: 1
A79: Rasio agen suspended (saat ini) | B79: =Pengguna!B89/Pengguna!B81 -> 0.015301902
A80: Kasus rekonsiliasi terbuka (saat ini) | B80: 7
...

Sheet Funnel_Kohort
A1: Funnel Aktivasi & Retensi Kohort
A2: Kohort daftar bulan lalu, jendela 30 hari sejak tanggal daftar. Retensi = agen aktif.
A3: DATA CONTOH untuk uji format export. Angka ilustrasi, bukan data nyata RumahAgen.
A5: Tahap | B5: Jumlah agen | C5: % dari pendaftar
A6: Daftar | B6: 1000 | C6: =B6/$B$6 -> 1
A7: Terverifikasi | B7: 812 | C7: =B7/$B$6 -> 0.812
A8: Listing pertama dipublikasikan | B8: 574 | C8: =B8/$B$6 -> 0.574
A9: Lead pertama | B9: 341 | C9: =B9/$B$6 -> 0.341
A10: Pembayaran pertama | B10: 96 | C10: =B10/$B$6 -> 0.096
A13: Kohort | B13: M0 | C13: M1 | D13: M2 | E13: M3 | F13: M4 | G13: M5
A14: Apr 2026 | B14: 1 | C14: 0.71 | D14: 0.62 | E14: 0.55 | F14: 0.51 | G14: 0.48
A15: Mei 2026 | B15: 1 | C15: 0.74 | D15: 0.64 | E15: 0.57 | F15: 0.52
A16: Jun 2026 | B16: 1 | C16: 0.76 | D16: 0.66 | E16: 0.59
A17: Jul 2026 | B17: 1 | C17: 0.78 | D17: 0.68
A18: Agu 2026 | B18: 1 | C18: 0.8
A19: Sep 2026 | B19: 1

Sheet Definisi
A1: Definisi Metrik (ringkas, v1.1)
A2: Sumber lengkap: docs/analytics/METRIC_DEFINITIONS_v1.md
A3: DATA CONTOH untuk uji format export. Angka ilustrasi, bukan data nyata RumahAgen.
A5: Istilah | B5: Definisi
A6: Zona waktu | B6: WIB; hari berganti 00:00 WIB; tanggal transaksi = paid_at
A7: Agen aktif | B7: Minimal 1 aktivitas bermakna dalam 30 hari; staf, akun uji, terhapus dikeluarkan
A8: Lead | B8: Klik CTA WhatsApp; lead unik didedup per pengunjung per listing per hari; klik pemilik dan bot dikeluarkan
A9: Transaksi sukses | B9: settlement/capture dan verification_state = verified
A10: Net | B10: Gross dikurangi refund dan chargeback
A11: MRR / ARR | B11: Langganan tahunan dibagi 12; ARR = MRR x 12; free membership tidak dihitung
A12: Churn langganan | B12: Berakhir tanpa perpanjangan setelah masa tenggang 7 hari
A13: Completion rate | B13: Per kohort pendaftaran
A14: Batasan | B14: Tren agen suspended dan organisasi ditutup tidak ditampilkan; take rate tidak dipakai
